Workbook

Sheet Inputs
A1: Provisa Net-Revenue Model — Inputs (yellow = adjustable knob)
A2: Rates are live Lemon Squeezy / GCP prices as of 2026-09-16 (from the internal pricing plan). Usage and customer counts are illustrative assumptions.
A4: Rate card
A5: Tier | B5: Base fee/mo | C5: Included active-hrs | D5: Overage $/hr | E5: Included GB | F5: Egress overage $/GB
A6: Starter | B6: 25 | C6: 19 | D6: 1.3 | E6: 25 | F6: 0.48
A7: Pro S | B7: 99 | C7: 66 | D7: 1.5 | E7: 50 | F7: 0.48
A8: Pro M | B8: 199 | C8: 72 | D8: 2.75 | E8: 100 | F8: 0.48
A9: Pro L | B9: 399 | C9: 72 | D9: 5.5 | E9: 200 | F9: 0.48
A11: Usage & customer mix
A12: Tier | B12: Customers (count) | C12: Active-hrs used/mo | D12: Egress used/mo (GB)
A13: Starter | B13: 30 | C13: 40 | D13: 15
A14: Pro S | B14: 12 | C14: 90 | D14: 60
A15: Pro M | B15: 5 | C15: 100 | D15: 130
A16: Pro L | B16: 3 | C16: 110 | D16: 250
A18: Compute cost basis
A19: GKE Autopilot: $/vCPU-hr | B19: 0.0445
A20: GKE Autopilot: $/GiB-hr | B20: 0.0049
A21: Shared shard pod: vCPU | B21: 6
A22: Shared shard pod: GiB | B22: 24
A23: Assumed concurrent Starter orgs per shard-hour | B23: 4 | C23: < biggest unverified lever in the model
A24: Pro S compute: n2-highmem-4 $/hr (on-demand) | B24: 0.26
A25: Pro M compute: n2-highmem-8 $/hr (on-demand) | B25: 0.52
A26: Pro L compute: n2-highmem-16 $/hr (on-demand) | B26: 1.05
A27: Provisa's own egress cost $/GB (GCP->internet) | B27: 0.12
A28: Fixed floor $/mo (Cloud SQL db-f1-micro etc.) | B28: 9
A30: Derived: shared shard $/hr | B30: =B21*B19+B22*B20
A31: Derived: shared compute $/hr per Starter org | B31: =B30/B23
A33: On-prem licensing — flat per-core model (cluster-scoped key; see note) | C33: < cluster-key sum-check holds only within one cluster's key exchange; cannot stop a copied key powering a separate cluster
A34: Free-tier scope: cluster-core cap (self-attested, unenforced) | B34: 8 | C34: < no runtime gate exists (library); this is a license-terms limit only — the lever is no support/SLA/updates, not a block
A35: Free-tier scope: max company annual revenue (self-attested, unenforced) | B35: 1000000 | C35: < both this and the core cap must hold — self-attested at signup, unenforced, audit-rights clause backs it
A36: Free-tier on-prem installs (informational only, $0 rev) | B36: 0
A37: Support-only SKU: $/yr (24hr: defect confirm/feature clarify + resolution ETA) | B37: 10000
A38: Support-only SKU: delivery cost % | B38: 0.4 | C38: < placeholder; labor-heavy relative to the $10K ticket
A39: Support-only SKU: subscribers (count) | B39: 0
A40: Rate $/core/yr | B40: 3000
A41: GiB mem bundled per licensed core (informational, not billed) | B41: 4
A42: Delivery/support cost, % of license revenue | B42: 0.25 | C42: < placeholder; raised from 20% per market-comp review (real fully-loaded cost, not just a floor)
A43: Licensed cores (this deal, cluster total) | B43: 48
A44: On-prem deals (count) | B44: 0
A46: Add-on SKUs (placeholder rates)
...

Sheet Model
A1: Provisa Net-Revenue Projection — Model
A2: Customer counts come from Inputs!B. Change a yellow cell on Inputs to see outcomes recompute here.
A4: Tier | B4: Customers | C4: Overage hrs/org | D4: Overage GB/org | E4: Revenue/org | F4: Cost/org | G4: Margin/org | H4: Fleet revenue | I4: Fleet cost
A5: Starter | B5: =Inputs!B13 | C5: =MAX(0,Inputs!C13-Inputs!C6) | D5: =MAX(0,Inputs!D13-Inputs!E6) | E5: =Inputs!B6+C5*Inputs!D6+D5*Inputs!F6 | F5: =Inputs!C13*Inputs!$B$31+Inputs!D13*Inputs!$B$27 | G5: =E5-F5 | H5: =B5*E5 | I5: =B5*F5
A6: Pro S | B6: =Inputs!B14 | C6: =MAX(0,Inputs!C14-Inputs!C7) | D6: =MAX(0,Inputs!D14-Inputs!E7) | E6: =Inputs!B7+C6*Inputs!D7+D6*Inputs!F7 | F6: =Inputs!C14*Inputs!$B$24+Inputs!D14*Inputs!$B$27 | G6: =E6-F6 | H6: =B6*E6 | I6: =B6*F6
A7: Pro M | B7: =Inputs!B15 | C7: =MAX(0,Inputs!C15-Inputs!C8) | D7: =MAX(0,Inputs!D15-Inputs!E8) | E7: =Inputs!B8+C7*Inputs!D8+D7*Inputs!F8 | F7: =Inputs!C15*Inputs!$B$25+Inputs!D15*Inputs!$B$27 | G7: =E7-F7 | H7: =B7*E7 | I7: =B7*F7
A8: Pro L | B8: =Inputs!B16 | C8: =MAX(0,Inputs!C16-Inputs!C9) | D8: =MAX(0,Inputs!D16-Inputs!E9) | E8: =Inputs!B9+C8*Inputs!D9+D8*Inputs!F9 | F8: =Inputs!C16*Inputs!$B$26+Inputs!D16*Inputs!$B$27 | G8: =E8-F8 | H8: =B8*E8 | I8: =B8*F8
A9: Fleet total | B9: =SUM(B5:B8) | H9: =SUM(H5:H8) | I9: =SUM(I5:I8)
A11: Summary
A12: Total revenue | B12: =H9
A13: Total direct cost | B13: =I9
A14: Fixed floor | B14: =Inputs!B28
A15: Net (monthly) | B15: =B12-B13-B14
A16: Net (annualized) | B16: =B15*12
A17: Net margin % | B17: =B15/B12

Sheet Scenario - $1M Net
A1: Scenario: customer mix to clear $1M/yr net profit
A2: Same rate card / per-org usage / compute cost as Inputs, but its own customer-count knobs (yellow, this sheet only) — the base mix scaled ~15.8x. Edit the yellow counts to explore other paths to $1M.
A4: Tier | B4: Customers | C4: Overage hrs/org | D4: Overage GB/org | E4: Revenue/org | F4: Cost/org | G4: Margin/org | H4: Fleet revenue | I4: Fleet cost
A5: Starter | B5: 473 | C5: =MAX(0,Inputs!C13-Inputs!C6) | D5: =MAX(0,Inputs!D13-Inputs!E6) | E5: =Inputs!B6+C5*Inputs!D6+D5*Inputs!F6 | F5: =Inputs!C13*Inputs!$B$31+Inputs!D13*Inputs!$B$27 | G5: =E5-F5 | H5: =B5*E5 | I5: =B5*F5
A6: Pro S | B6: 189 | C6: =MAX(0,Inputs!C14-Inputs!C7) | D6: =MAX(0,Inputs!D14-Inputs!E7) | E6: =Inputs!B7+C6*Inputs!D7+D6*Inputs!F7 | F6: =Inputs!C14*Inputs!$B$24+Inputs!D14*Inputs!$B$27 | G6: =E6-F6 | H6: =B6*E6 | I6: =B6*F6
A7: Pro M | B7: 79 | C7: =MAX(0,Inputs!C15-Inputs!C8) | D7: =MAX(0,Inputs!D15-Inputs!E8) | E7: =Inputs!B8+C7*Inputs!D8+D7*Inputs!F8 | F7: =Inputs!C15*Inputs!$B$25+Inputs!D15*Inputs!$B$27 | G7: =E7-F7 | H7: =B7*E7 | I7: =B7*F7
A8: Pro L | B8: 47 | C8: =MAX(0,Inputs!C16-Inputs!C9) | D8: =MAX(0,Inputs!D16-Inputs!E9) | E8: =Inputs!B9+C8*Inputs!D9+D8*Inputs!F9 | F8: =Inputs!C16*Inputs!$B$26+Inputs!D16*Inputs!$B$27 | G8: =E8-F8 | H8: =B8*E8 | I8: =B8*F8
A9: Fleet total | B9: =SUM(B5:B8) | H9: =SUM(H5:H8) | I9: =SUM(I5:I8)
A11: Summary
A12: Total revenue | B12: =H9
A13: Total direct cost | B13: =I9
A14: Fixed floor | B14: =Inputs!B28
A15: Net (monthly) | B15: =B12-B13-B14
A16: Net (annualized) | B16: =B15*12
A17: Net margin % | B17: =B15/B12

Sheet On-Prem
A1: On-Prem Licensing — Revenue Model
A2: Single per-core model, no coordinator/worker or hardware-class distinction — a core is a core. Cluster-scoped license key (see Inputs note) — real within a cluster's key exchange, honor-system across separate clusters.
A4: License revenue per deal
A5: Bundled GiB mem (informational, not billed) | B5: =Inputs!B43*Inputs!B41
A6: Total license revenue/deal | B6: =Inputs!B43*Inputs!B40
A7: Delivery/support cost/deal | B7: =B6*Inputs!B42
A8: Margin/deal | B8: =B6-B7
A10: Deal count (from Inputs) | B10: =Inputs!B44
A11: Total revenue/yr | B11: =B10*B6
A12: Total cost/yr | B12: =B10*B7
A13: Net on-prem/yr | B13: =B11-B12
A15: Support-only SKU (free-tier upsell)
A16: Subscribers (from Inputs) | B16: =Inputs!B39
A17: Revenue/yr | B17: =B16*Inputs!B37
A18: Cost/yr | B18: =B17*Inputs!B38
A19: Net/yr | B19: =B17-B18

Sheet Add-Ons
A1: Add-On SKUs — Premium Connectors + LLM Reasoning
A2: Sold on top of either SaaS or on-prem. Rates are placeholders — no comparable-vendor research done on these yet.
A4: Premium connectors: revenue/yr | B4: =Inputs!B48*Inputs!B47
A5: LLM validated-reasoning: revenue/yr | B5: =Inputs!B50*Inputs!B49*12
A6: Total add-on revenue/yr | B6: =B4+B5
A7: Delivery cost/yr | B7: =B6*Inputs!B51
A8: Net add-on/yr | B8: =B6-B7

Sheet Scenario - Mixed
A1: Scenario: mixed SaaS + on-prem path to ~$1M net
A2: SaaS counts below are this sheet's own knobs (half the pure-SaaS $1M mix). On-prem deals further down are also this sheet's own knobs, priced from the same single per-core rate on Inputs.
A4: Tier | B4: Customers | C4: Overage hrs/org | D4: Overage GB/org | E4: Revenue/org | F4: Cost/org | G4: Margin/org | H4: Fleet revenue | I4: Fleet cost
A5: Starter | B5: 220 | C5: =MAX(0,Inputs!C13-Inputs!C6) | D5: =MAX(0,Inputs!D13-Inputs!E6) | E5: =Inputs!B6+C5*Inputs!D6+D5*Inputs!F6 | F5: =Inputs!C13*Inputs!$B$31+Inputs!D13*Inputs!$B$27 | G5: =E5-F5 | H5: =B5*E5 | I5: =B5*F5
A6: Pro S | B6: 90 | C6: =MAX(0,Inputs!C14-Inputs!C7) | D6: =MAX(0,Inputs!D14-Inputs!E7) | E6: =Inputs!B7+C6*Inputs!D7+D6*Inputs!F7 | F6: =Inputs!C14*Inputs!$B$24+Inputs!D14*Inputs!$B$27 | G6: =E6-F6 | H6: =B6*E6 | I6: =B6*F6
A7: Pro M | B7: 38 | C7: =MAX(0,Inputs!C15-Inputs!C8) | D7: =MAX(0,Inputs!D15-Inputs!E8) | E7: =Inputs!B8+C7*Inputs!D8+D7*Inputs!F8 | F7: =Inputs!C15*Inputs!$B$25+Inputs!D15*Inputs!$B$27 | G7: =E7-F7 | H7: =B7*E7 | I7: =B7*F7
A8: Pro L | B8: 22 | C8: =MAX(0,Inputs!C16-Inputs!C9) | D8: =MAX(0,Inputs!D16-Inputs!E9) | E8: =Inputs!B9+C8*Inputs!D9+D8*Inputs!F9 | F8: =Inputs!C16*Inputs!$B$26+Inputs!D16*Inputs!$B$27 | G8: =E8-F8 | H8: =B8*E8 | I8: =B8*F8
A9: Fleet total | B9: =SUM(B5:B8) | H9: =SUM(H5:H8) | I9: =SUM(I5:I8)
A11: Summary
A12: Total revenue | B12: =H9
A13: Total direct cost | B13: =I9
A14: Fixed floor | B14: =Inputs!B28
A15: Net (monthly) | B15: =B12-B13-B14
A16: Net (annualized) | B16: =B15*12
A17: Net margin % | B17: =B15/B12
A19: On-prem (per-core)
A20: Deals (this scenario) | B20: 3
A21: Revenue/deal | B21: =Inputs!B43*Inputs!B40
A22: Margin/deal (after support %) | B22: =B21*(1-Inputs!B42)
A23: On-prem: net/yr | B23: =B20*B22
A25: Combined summary
A26: SaaS net/yr | B26: =B16
A27: On-prem net/yr | B27: =B23
A28: Combined net/yr | B28: =B26+B23

Sheet Combined
A1: Combined Net — SaaS ($1M scenario sheet) + On-Prem
A2: Turn on-prem deal counts up on Inputs to see how licensing reduces the SaaS org count needed.
A4: SaaS net/yr (Scenario - $1M Net sheet) | B4: ='Scenario - $1M Net'!B16
A5: On-prem net/yr | B5: =On-Prem!B13
A6: Support-only SKU net/yr (free-tier upsell) | B6: =On-Prem!B19
A7: Add-on SKUs net/yr (connectors + LLM reasoning) | B7: ='Add-Ons'!B8
A8: Combined net/yr | B8: =B4+B5+B6+B7
